Workbook
Name d_0.03: #REF!
Name d_0.1: #REF!
Name load_ratio: #REF!
Name percent_of_load_served: #REF!

Sheet Overview

Sheet Inputs&OutputSummary
B1: RURAL AFRICAN HOUSEHOLD LOAD PROFILES
B4: INPUTS | F4: OUTPUTS
H5: LOAD PROFILE OUTPUT TABLE (kW)
B6: HOUSEHOLD AND COMMERCIAL INPUTS* | H6: Total Household Load | I6: Total Commercial Load | J6: Total Household + Commercial Load
B7: HOUSEHOLD INPUTS | G7: 0 | H7: =($C$8*CoincidenceFactor_HouseholdLoad!P30)/1000 -> 0.86243458 | I7: =(CommercialLoadProfiles!C5)/1000 -> 0.3268 | J7: =SUM(H7,I7) -> 1.1892346
B8: Number of Households: | C8: 100 | G8: 0.041666667 | H8: =($C$8*CoincidenceFactor_HouseholdLoad!P31)/1000 -> 0.60610022 | I8: =(CommercialLoadProfiles!C6)/1000 -> 0.3268 | J8: =SUM(H8,I8) -> 0.93290022
B9: % of High Income Households | C9: 0.3333 | G9: 0.083333333 | H9: =($C$8*CoincidenceFactor_HouseholdLoad!P32)/1000 -> 0.46486268 | I9: =(CommercialLoadProfiles!C7)/1000 -> 0.3268 | J9: =SUM(H9,I9) -> 0.79166268
B10: % of Medium Income Households | C10: 0.3333 | G10: 0.125 | H10: =($C$8*CoincidenceFactor_HouseholdLoad!P33)/1000 -> 0.39860347 | I10: =(CommercialLoadProfiles!C8)/1000 -> 0.3268 | J10: =SUM(H10,I10) -> 0.72540347
B11: % of Low Income Households | C11: 0.3333 | G11: 0.16666667 | H11: =($C$8*CoincidenceFactor_HouseholdLoad!P34)/1000 -> 0.40046412 | I11: =(CommercialLoadProfiles!C9)/1000 -> 0.3268 | J11: =SUM(H11,I11) -> 0.72726412
B12: Check that the % households adds up to 100%: | C12: =SUM(C9:C11) -> 0.9999 | G12: 0.20833333 | H12: =($C$8*CoincidenceFactor_HouseholdLoad!P35)/1000 -> 0.43433156 | I12: =(CommercialLoadProfiles!C10)/1000 -> 0.3268 | J12: =SUM(H12,I12) -> 0.76113156
B13: =IF(C12<99.9%,"The % households do NOT equal 100%, CHECK PERCENTAGES",IF(C12>99.9%,IF(C12<=100%,"The % households equals 100%","The % households do NOT equal 100%, CHECK PERCENTAGES"))) -> The % households equals 100% | G13: 0.25 | H13: =($C$8*CoincidenceFactor_HouseholdLoad!P36)/1000 -> 0.52537746 | I13: =(CommercialLoadProfiles!C11)/1000 -> 0.5148 | J13: =SUM(H13,I13) -> 1.0401775
B14: COMMERCIAL INPUTS | G14: 0.29166667 | H14: =($C$8*CoincidenceFactor_HouseholdLoad!P37)/1000 -> 0.67347848 | I14: =(CommercialLoadProfiles!C12)/1000 -> 0.8356 | J14: =SUM(H14,I14) -> 1.5090785
B15: Number of Water Pumping Operations | C15: 0 | G15: 0.33333333 | H15: =($C$8*CoincidenceFactor_HouseholdLoad!P38)/1000 -> 1.1184673 | I15: =(CommercialLoadProfiles!C13)/1000 -> 0.952 | J15: =SUM(H15,I15) -> 2.0704673
B16: Number of Milling Operations | C16: 0 | G16: 0.375 | H16: =($C$8*CoincidenceFactor_HouseholdLoad!P39)/1000 -> 1.2460004 | I16: =(CommercialLoadProfiles!C14)/1000 -> 1.0766 | J16: =SUM(H16,I16) -> 2.3226004
B17: Number of Small Shops | C17: 2 | G17: 0.41666667 | H17: =($C$8*CoincidenceFactor_HouseholdLoad!P40)/1000 -> 1.2782397 | I17: =(CommercialLoadProfiles!C15)/1000 -> 1.0766 | J17: =SUM(H17,I17) -> 2.3548397
B18: Number of Schools | C18: 1 | G18: 0.45833333 | H18: =($C$8*CoincidenceFactor_HouseholdLoad!P41)/1000 -> 1.2624571 | I18: =(CommercialLoadProfiles!C16)/1000 -> 1.0766 | J18: =SUM(H18,I18) -> 2.3390571
B19: Number of Clinics | C19: 0 | G19: 0.5 | H19: =($C$8*CoincidenceFactor_HouseholdLoad!P42)/1000 -> 0.96463686 | I19: =(CommercialLoadProfiles!C17)/1000 -> 1.0766 | J19: =SUM(H19,I19) -> 2.0412369
B20: Number of Street Lights | C20: 0 | G20: 0.54166667 | H20: =($C$8*CoincidenceFactor_HouseholdLoad!P43)/1000 -> 0.88417074 | I20: =(CommercialLoadProfiles!C18)/1000 -> 1.0766 | J20: =SUM(H20,I20) -> 1.9607707
B21: *Changeable inputs are located in cells C8 to C11 and C15 to C20 | G21: 0.58333333 | H21: =($C$8*CoincidenceFactor_HouseholdLoad!P44)/1000 -> 0.85619437 | I21: =(CommercialLoadProfiles!C19)/1000 -> 1.0766 | J21: =SUM(H21,I21) -> 1.9327944
G22: 0.625 | H22: =($C$8*CoincidenceFactor_HouseholdLoad!P45)/1000 -> 0.79535296 | I22: =(CommercialLoadProfiles!C20)/1000 -> 1.0766 | J22: =SUM(H22,I22) -> 1.871953
G23: 0.66666667 | H23: =($C$8*CoincidenceFactor_HouseholdLoad!P46)/1000 -> 1.0230444 | I23: =(CommercialLoadProfiles!C21)/1000 -> 1.0214 | J23: =SUM(H23,I23) -> 2.0444444
G24: 0.70833333 | H24: =($C$8*CoincidenceFactor_HouseholdLoad!P47)/1000 -> 1.7882287 | I24: =(CommercialLoadProfiles!C22)/1000 -> 0.6924 | J24: =SUM(H24,I24) -> 2.4806287
G25: 0.75 | H25: =($C$8*CoincidenceFactor_HouseholdLoad!P48)/1000 -> 2.6948372 | I25: =(CommercialLoadProfiles!C23)/1000 -> 0.5984 | J25: =SUM(H25,I25) -> 3.2932372
G26: 0.79166667 | H26: =($C$8*CoincidenceFactor_HouseholdLoad!P49)/1000 -> 4.0579442 | I26: =(CommercialLoadProfiles!C24)/1000 -> 0.6372 | J26: =SUM(H26,I26) -> 4.6951442
G27: 0.83333333 | H27: =($C$8*CoincidenceFactor_HouseholdLoad!P50)/1000 -> 5.2234401 | I27: =(CommercialLoadProfiles!C25)/1000 -> 0.6372 | J27: =SUM(H27,I27) -> 5.8606401
G28: 0.875 | H28: =($C$8*CoincidenceFactor_HouseholdLoad!P51)/1000 -> 4.9098548 | I28: =(CommercialLoadProfiles!C26)/1000 -> 0.6372 | J28: =SUM(H28,I28) -> 5.5470548
G29: 0.91666667 | H29: =($C$8*CoincidenceFactor_HouseholdLoad!P52)/1000 -> 3.1541046 | I29: =(CommercialLoadProfiles!C27)/1000 -> 0.482 | J29: =SUM(H29,I29) -> 3.6361046
G30: 0.95833333 | H30: =($C$8*CoincidenceFactor_HouseholdLoad!P53)/1000 -> 1.5453238 | I30: =(CommercialLoadProfiles!C28)/1000 -> 0.3268 | J30: =SUM(H30,I30) -> 1.8721238
G31: Total kWh/day | H31: =SUM(H7:H30) -> 37.167949 | I31: =SUM(I7:I30) -> 16.832 | J31: =SUM(J7:J30) -> 53.999949
G32: Total kWh/year | H32: =(365*H31) -> 13566.302 | I32: =365*I31 -> 6143.68 | J32: =365*J31 -> 19709.982
G33: Max kW/day | H33: =MAX(H7:H30) -> 5.2234401 | I33: =MAX(I7:I30) -> 1.0766 | J33: =MAX(J7:J30) -> 5.8606401
G34: Min kW/day | H34: =MIN(H7:H30) -> 0.39860347 | I34: =MIN(I7:I30) -> 0.3268 | J34: =MIN(J7:J30) -> 0.72540347

Sheet HouseholdLoadProfiles
B1: RURAL AFRICAN HOUSEHOLD LOAD PROFILES
B3: SUMMARY OF RURAL AFRICAN HOUSEHOLD LOAD PROFILES (W)
C4: High Income Household | D4: Medium Income Household | E4: Low Income Household | F4: All Households Assuming Varying % High, Medium, and Low Income
B5: 0 | C5: =C72 -> 8.5 | D5: =C85 -> 2 | E5: =C98 -> 0.5 | F5: ='Inputs&OutputSummary'!$C$9*HouseholdLoadProfiles!C5+'Inputs&OutputSummary'!$C$10*HouseholdLoadProfiles!D5+'Inputs&OutputSummary'!$C$11*HouseholdLoadProfiles!E5 -> 3.6663
B6: 0.041666667 | C6: =D72 -> 8.5 | D6: =D85 -> 2 | E6: =D98 -> 0.5 | F6: ='Inputs&OutputSummary'!$C$9*HouseholdLoadProfiles!C6+'Inputs&OutputSummary'!$C$10*HouseholdLoadProfiles!D6+'Inputs&OutputSummary'!$C$11*HouseholdLoadProfiles!E6 -> 3.6663
B7: 0.083333333 | C7: =E72 -> 8.5 | D7: =E85 -> 2 | E7: =E98 -> 0.5 | F7: ='Inputs&OutputSummary'!$C$9*HouseholdLoadProfiles!C7+'Inputs&OutputSummary'!$C$10*HouseholdLoadProfiles!D7+'Inputs&OutputSummary'!$C$11*HouseholdLoadProfiles!E7 -> 3.6663
B8: 0.125 | C8: =F72 -> 8.5 | D8: =F85 -> 2 | E8: =F98 -> 0.5 | F8: ='Inputs&OutputSummary'!$C$9*HouseholdLoadProfiles!C8+'Inputs&OutputSummary'!$C$10*HouseholdLoadProfiles!D8+'Inputs&OutputSummary'!$C$11*HouseholdLoadProfiles!E8 -> 3.6663
B9: 0.16666667 | C9: =G72 -> 8.5 | D9: =G85 -> 2 | E9: =G98 -> 0.5 | F9: ='Inputs&OutputSummary'!$C$9*HouseholdLoadProfiles!C9+'Inputs&OutputSummary'!$C$10*HouseholdLoadProfiles!D9+'Inputs&OutputSummary'!$C$11*HouseholdLoadProfiles!E9 -> 3.6663
B10: 0.20833333 | C10: =H72 -> 8.5 | D10: =H85 -> 2 | E10: =H98 -> 0.5 | F10: ='Inputs&OutputSummary'!$C$9*HouseholdLoadProfiles!C10+'Inputs&OutputSummary'!$C$10*HouseholdLoadProfiles!D10+'Inputs&OutputSummary'!$C$11*HouseholdLoadProfiles!E10 -> 3.6663
B11: 0.25 | C11: =I72 -> 10.012 | D11: =I85 -> 2.88 | E11: =I98 -> 0.828 | F11: ='Inputs&OutputSummary'!$C$9*HouseholdLoadProfiles!C11+'Inputs&OutputSummary'!$C$10*HouseholdLoadProfiles!D11+'Inputs&OutputSummary'!$C$11*HouseholdLoadProfiles!E11 -> 4.572876
B12: 0.29166667 | C12: =J72 -> 10.012 | D12: =J85 -> 2.88 | E12: =J98 -> 0.828 | F12: ='Inputs&OutputSummary'!$C$9*HouseholdLoadProfiles!C12+'Inputs&OutputSummary'!$C$10*HouseholdLoadProfiles!D12+'Inputs&OutputSummary'!$C$11*HouseholdLoadProfiles!E12 -> 4.572876
B13: 0.33333333 | C13: =K72 -> 29.862 | D13: =K85 -> 8.9425 | E13: =K98 -> 1.9405 | F13: ='Inputs&OutputSummary'!$C$9*HouseholdLoadProfiles!C13+'Inputs&OutputSummary'!$C$10*HouseholdLoadProfiles!D13+'Inputs&OutputSummary'!$C$11*HouseholdLoadProfiles!E13 -> 13.580308
B14: 0.375 | C14: =L72 -> 29.862 | D14: =L85 -> 8.9425 | E14: =L98 -> 1.9405 | F14: ='Inputs&OutputSummary'!$C$9*HouseholdLoadProfiles!C14+'Inputs&OutputSummary'!$C$10*HouseholdLoadProfiles!D14+'Inputs&OutputSummary'!$C$11*HouseholdLoadProfiles!E14 -> 13.580308
B15: 0.41666667 | C15: =M72 -> 29.862 | D15: =M85 -> 8.9425 | E15: =M98 -> 1.9405 | F15: ='Inputs&OutputSummary'!$C$9*HouseholdLoadProfiles!C15+'Inputs&OutputSummary'!$C$10*HouseholdLoadProfiles!D15+'Inputs&OutputSummary'!$C$11*HouseholdLoadProfiles!E15 -> 13.580308
B16: 0.45833333 | C16: =N72 -> 32.13 | D16: =N85 -> 10.2625 | E16: =N98 -> 2.4325 | F16: ='Inputs&OutputSummary'!$C$9*HouseholdLoadProfiles!C16+'Inputs&OutputSummary'!$C$10*HouseholdLoadProfiles!D16+'Inputs&OutputSummary'!$C$11*HouseholdLoadProfiles!E16 -> 14.940173
B17: 0.5 | C17: =O72 -> 17.98 | D17: =O85 -> 5.325 | E17: =O98 -> 1.545 | F17: ='Inputs&OutputSummary'!$C$9*HouseholdLoadProfiles!C17+'Inputs&OutputSummary'!$C$10*HouseholdLoadProfiles!D17+'Inputs&OutputSummary'!$C$11*HouseholdLoadProfiles!E17 -> 8.282505
B18: 0.54166667 | C18: =P72 -> 17.98 | D18: =P85 -> 5.325 | E18: =P98 -> 1.545 | F18: ='Inputs&OutputSummary'!$C$9*HouseholdLoadProfiles!C18+'Inputs&OutputSummary'!$C$10*HouseholdLoadProfiles!D18+'Inputs&OutputSummary'!$C$11*HouseholdLoadProfiles!E18 -> 8.282505
B19: 0.58333333 | C19: =Q72 -> 17.98 | D19: =Q85 -> 5.325 | E19: =Q98 -> 1.545 | F19: ='Inputs&OutputSummary'!$C$9*HouseholdLoadProfiles!C19+'Inputs&OutputSummary'!$C$10*HouseholdLoadProfiles!D19+'Inputs&OutputSummary'!$C$11*HouseholdLoadProfiles!E19 -> 8.282505
B20: 0.625 | C20: =R72 -> 11.35 | D20: =R85 -> 2.5625 | E20: =R98 -> 0.6125 | F20: ='Inputs&OutputSummary'!$C$9*HouseholdLoadProfiles!C20+'Inputs&OutputSummary'!$C$10*HouseholdLoadProfiles!D20+'Inputs&OutputSummary'!$C$11*HouseholdLoadProfiles!E20 -> 4.8411825
B21: 0.66666667 | C21: =S72 -> 11.35 | D21: =S85 -> 2.5625 | E21: =S98 -> 0.6125 | F21: ='Inputs&OutputSummary'!$C$9*HouseholdLoadProfiles!C21+'Inputs&OutputSummary'!$C$10*HouseholdLoadProfiles!D21+'Inputs&OutputSummary'!$C$11*HouseholdLoadProfiles!E21 -> 4.8411825
B22: 0.70833333 | C22: =T72 -> 28.36 | D22: =T85 -> 13.15 | E22: =T98 -> 4.54 | F22: ='Inputs&OutputSummary'!$C$9*HouseholdLoadProfiles!C22+'Inputs&OutputSummary'!$C$10*HouseholdLoadProfiles!D22+'Inputs&OutputSummary'!$C$11*HouseholdLoadProfiles!E22 -> 15.348465
B23: 0.75 | C23: =U72 -> 42.59 | D23: =U85 -> 21.095 | E23: =U98 -> 8.095 | F23: ='Inputs&OutputSummary'!$C$9*HouseholdLoadProfiles!C23+'Inputs&OutputSummary'!$C$10*HouseholdLoadProfiles!D23+'Inputs&OutputSummary'!$C$11*HouseholdLoadProfiles!E23 -> 23.924274
B24: 0.79166667 | C24: =V72 -> 75.87 | D24: =V85 -> 40.29 | E24: =V98 -> 16.3 | F24: ='Inputs&OutputSummary'!$C$9*HouseholdLoadProfiles!C24+'Inputs&OutputSummary'!$C$10*HouseholdLoadProfiles!D24+'Inputs&OutputSummary'!$C$11*HouseholdLoadProfiles!E24 -> 44.148918
B25: 0.83333333 | C25: =W72 -> 112.77 | D25: =W85 -> 60.54 | E25: =W98 -> 23.5 | F25: ='Inputs&OutputSummary'!$C$9*HouseholdLoadProfiles!C25+'Inputs&OutputSummary'!$C$10*HouseholdLoadProfiles!D25+'Inputs&OutputSummary'!$C$11*HouseholdLoadProfiles!E25 -> 65.596773
B26: 0.875 | C26: =X72 -> 107.35 | D26: =X85 -> 56.11 | E26: =X98 -> 21.355 | F26: ='Inputs&OutputSummary'!$C$9*HouseholdLoadProfiles!C26+'Inputs&OutputSummary'!$C$10*HouseholdLoadProfiles!D26+'Inputs&OutputSummary'!$C$11*HouseholdLoadProfiles!E26 -> 61.598839
B27: 0.91666667 | C27: =Y72 -> 55.41 | D27: =Y85 -> 28.015 | E27: =Y98 -> 11.21 | F27: ='Inputs&OutputSummary'!$C$9*HouseholdLoadProfiles!C27+'Inputs&OutputSummary'!$C$10*HouseholdLoadProfiles!D27+'Inputs&OutputSummary'!$C$11*HouseholdLoadProfiles!E27 -> 31.541846
B28: 0.95833333 | C28: =Z72 -> 15.25 | D28: =Z85 -> 6.5 | E28: =Z98 -> 2.75 | F28: ='Inputs&OutputSummary'!$C$9*HouseholdLoadProfiles!C28+'Inputs&OutputSummary'!$C$10*HouseholdLoadProfiles!D28+'Inputs&OutputSummary'!$C$11*HouseholdLoadProfiles!E28 -> 8.16585
B29: Total Wh/day/household: | C29: =SUM(C5:C28) -> 706.98 | D29: =SUM(D5:D28) -> 301.65 | E29: =SUM(E5:E28) -> 106.52 | F29: =SUM(F5:F28) -> 371.67949
B30: Total kWh/year/household: | C30: =365*(C29)/1000 -> 258.0477 | D30: =365*(D29)/1000 -> 110.10225 | E30: =365*(E29)/1000 -> 38.8798 | F30: =365*(F29)/1000 -> 135.66302
B32: ASSUMED APPLIANCE WATTAGE & COUNT | H32: APPLIANCE OWNERSHIP SUMMARY 2 | M32: OVERALL APPLIANCE COUNT ACCOUNTING FOR % OWNERSHIP
C33: All Households | D33: High Income Household | E33: Medium Income Household | F33: Low Income Household | I33: High Income Household 3 | J33: Medium Income Household 4 | K33: Low Income Household 5 | N33: High Income Household | O33: Medium Income Household | P33: Low Income Household
C34: Appliance Wattage (W) | D34: Appliance Count | E34: Appliance Count | F34: Appliance Count | I34: % Ownership | J34: % Ownership | K34: % Ownership | N34: Appliance Count Accounting for % Ownership | O34: Appliance Count Accounting for % Ownership | P34: Appliance Count Accounting for % Ownership
B35: LOW WATTAGE APPLIANCES | H35: LOW WATTAGE APPLIANCES | M35: LOW WATTAGE APPLIANCES
B36: Lights | C36: 9 | D36: 3 | E36: 2 | F36: 1 | H36: Lights | I36: 1 | J36: 1 | K36: 1 | M36: Lights | N36: =D36*I36 -> 3 | O36: =E36*J36 -> 2 | P36: =F36*K36 -> 1
B37: Mobile Phone/Charger | C37: 8 | D37: 3 | E37: 2 | F37: 1 | H37: Mobile Phone/Charger | I37: 0.63 | J37: 0.55 | K37: 0.41 | M37: Mobile Phone/Charger | N37: =D37*I37 -> 1.89 | O37: =E37*J37 -> 1.1 | P37: =F37*K37 -> 0.41
B38: Radio | C38: 15 | D38: 1 | E38: 1 | F38: 1 | H38: Radio | I38: 0.76 | J38: 0.15 | K38: 0.03 | M38: Radio | N38: =D38*I38 -> 0.76 | O38: =E38*J38 -> 0.15 | P38: =F38*K38 -> 0.03
B39: HIGH WATTAGE APPLIANCES | H39: HIGH WATTAGE APPLIANCES | M39: HIGH WATTAGE APPLIANCES
B40: Television | C40: 150 | D40: 1 | E40: 1 | F40: 1 | H40: Television | I40: 0.82 | J40: 0.45 | K40: 0.16 | M40: Television | N40: =D40*I40 -> 0.82 | O40: =E40*J40 -> 0.45 | P40: =F40*K40 -> 0.16
B41: DVD Player | C41: 35 | D41: 1 | E41: 1 | F41: 1 | H41: DVD Player | I41: 0.38 | J41: 0.02 | K41: 0.03 | M41: DVD Player | N41: =D41*I41 -> 0.38 | O41: =E41*J41 -> 0.02 | P41: =F41*K41 -> 0.03
B42: Iron | C42: 1000 | D42: 1 | E42: 1 | F42: 1 | H42: Iron | I42: 0.34 | J42: 0.11 | K42: 0.02 | M42: Iron | N42: =D42*I42 -> 0.34 | O42: =E42*J42 -> 0.11 | P42: =F42*K42 -> 0.02
...

Sheet CommercialLoadProfiles
B1: RURAL AFRICAN COMMERCIAL LOAD PROFILES
B3: SUMMARY OF RURAL AFRICAN COMMERCIAL LOAD PROFILES (W)
B4: Energy Use: | C4: All of Commercial Entities
B5: 0 | C5: =C70 -> 326.8
B6: 0.041666667 | C6: =D70 -> 326.8
B7: 0.083333333 | C7: =E70 -> 326.8
B8: 0.125 | C8: =F70 -> 326.8
B9: 0.16666667 | C9: =G70 -> 326.8
B10: 0.20833333 | C10: =H70 -> 326.8
B11: 0.25 | C11: =I70 -> 514.8
B12: 0.29166667 | C12: =J70 -> 835.6
B13: 0.33333333 | C13: =K70 -> 952
B14: 0.375 | C14: =L70 -> 1076.6
B15: 0.41666667 | C15: =M70 -> 1076.6
B16: 0.45833333 | C16: =N70 -> 1076.6
B17: 0.5 | C17: =O70 -> 1076.6
B18: 0.54166667 | C18: =P70 -> 1076.6
B19: 0.58333333 | C19: =Q70 -> 1076.6
B20: 0.625 | C20: =R70 -> 1076.6
B21: 0.66666667 | C21: =S70 -> 1021.4
B22: 0.70833333 | C22: =T70 -> 692.4
B23: 0.75 | C23: =U70 -> 598.4
B24: 0.79166667 | C24: =V70 -> 637.2
B25: 0.83333333 | C25: =W70 -> 637.2
B26: 0.875 | C26: =X70 -> 637.2
B27: 0.91666667 | C27: =Y70 -> 482
B28: 0.95833333 | C28: =Z70 -> 326.8
B29: Total kWh/day: | C29: =SUM(C5:C28)/1000 -> 16.832
B30: Total kWh/year: | C30: =(365*C29) -> 6143.68
B32: ASSUMED COMMERCIAL ENTITY WATTAGE AND OPERATING HOURS
B33: Commercial Entity Type | C33: Operating Hours (Hours/Month) | D33: Per Unit Wattage (Watts) | E33: Montly Electricity Consumption (kWh/Month)
B34: Water Pumping 1 | C34: 217 | D34: 985 | E34: =(D34*C34)/1000 -> 213.745
B35: Milling 1 | C35: 217 | D35: 985 | E35: =(D35*C35)/1000 -> 213.745
B36: Small Shop (refrigerators, freezers, TV, lighting) 1 | C36: 261 | D36: 388 | E36: =(D36*C36)/1000 -> 101.268
B37: School (lighting, fans, computers) 2 | C37: 174 | D37: 940 | E37: =(D37*C37)/1000 -> 163.56
B38: Clinic (lighting, refrigerator, TV, misc.) 2 | C38: 174 | D38: 320 | E38: =(D38*C38)/1000 -> 55.68
B39: Street Lighting (on per light fixture basis) 2 | C39: 217 | D39: 20 | E39: =(D39*C39)/1000 -> 4.34
B40: 1 Power and Agriculture Nexus in Sub-Saharan Africa (2017)
B41: 2 Electrical Load Survey and Forecast for a Decentralized Hybrid Power System at Elebu, Kwara State, Nigeria (2015)
B43: HOURLY COMMERCIAL LOAD PROFILES
...

Sheet CoincidenceFactor_HouseholdLoad
D23: Min kW | P23: New Min kW
D24: =MIN(D30:D63) -> 3.6663 | P24: =MIN(P30:P63) -> 3.9860347
D25: Max kW | P25: New Max kW | Q25: Coincidence Factor
D26: =MAX(D30:D63) -> 65.596773 | P26: =MAX(P30:P63) -> 52.234401 | Q26: =P26/D26 -> 0.79629528
D27: Total Number of Households
D28: Percentage of Households Shifted | E28: 0.5 | F28: 0.15 | G28: 0.15 | H28: 0.05 | I28: 0.05 | J28: 0.025 | K28: 0.025 | L28: 0.02 | M28: 0.02 | N28: 0.005 | O28: 0.005 | P28: =SUM(E28:O28) -> 1
B29: Day of Week | C29: Hour of Day | D29: Original Load Profile | E29: No Shift | F29: +1 hour | G29: -1 hour | H29: +2 hour | I29: -2 hour | J29: +3 hour | K29: -3 hour | L29: +4 hour | M29: -4 hour | N29: +5 hour | O29: -5 hour | P29: Load Profile with 80% Coincidence Factor
B30: Generating Profile with 80% Coincidence Factor | C30: 1 | D30: =HouseholdLoadProfiles!F5 -> 3.6663 | E30: =$D30*E$28 -> 1.83315 | F30: =$D31*F$28 -> 0.549945 | G30: =$D58*G$28 -> 1.2248775 | H30: =$D32*H$28 -> 0.183315 | I30: =$D57*I$28 -> 1.5770923 | J30: =$D33*J$28 -> 0.0916575 | K30: =$D56*K$28 -> 1.539971 | L30: =$D34*L$28 -> 0.073326 | M30: =$D55*M$28 -> 1.3119355 | N30: =$D35*N$28 -> 0.0183315 | O30: =$D54*O$28 -> 0.22074459 | P30: =SUM(E30:O30) -> 8.6243458
B31: Generating Profile with 80% Coincidence Factor | C31: 2 | D31: =HouseholdLoadProfiles!F6 -> 3.6663 | E31: =$D31*E$28 -> 1.83315 | F31: =$D32*F$28 -> 0.549945 | G31: =$D30*G$28 -> 0.549945 | H31: =$D33*H$28 -> 0.183315 | I31: =$D58*I$28 -> 0.4082925 | J31: =$D34*J$28 -> 0.0916575 | K31: =$D57*K$28 -> 0.78854614 | L31: =$D35*L$28 -> 0.073326 | M31: =$D56*M$28 -> 1.2319768 | N31: =$D36*N$28 -> 0.02286438 | O31: =$D55*O$28 -> 0.32798386 | P31: =SUM(E31:O31) -> 6.0610022
B32: Generating Profile with 80% Coincidence Factor | C32: 3 | D32: =HouseholdLoadProfiles!F7 -> 3.6663 | E32: =$D32*E$28 -> 1.83315 | F32: =$D33*F$28 -> 0.549945 | G32: =$D31*G$28 -> 0.549945 | H32: =$D34*H$28 -> 0.183315 | I32: =$D30*I$28 -> 0.183315 | J32: =$D35*J$28 -> 0.0916575 | K32: =$D58*K$28 -> 0.20414625 | L32: =$D36*L$28 -> 0.09145752 | M32: =$D57*M$28 -> 0.63083691 | N32: =$D37*N$28 -> 0.02286438 | O32: =$D56*O$28 -> 0.3079942 | P32: =SUM(E32:O32) -> 4.6486268
B33: Generating Profile with 80% Coincidence Factor | C33: 4 | D33: =HouseholdLoadProfiles!F8 -> 3.6663 | E33: =$D33*E$28 -> 1.83315 | F33: =$D34*F$28 -> 0.549945 | G33: =$D32*G$28 -> 0.549945 | H33: =$D35*H$28 -> 0.183315 | I33: =$D31*I$28 -> 0.183315 | J33: =$D36*J$28 -> 0.1143219 | K33: =$D30*K$28 -> 0.0916575 | L33: =$D37*L$28 -> 0.09145752 | M33: =$D58*M$28 -> 0.163317 | N33: =$D38*N$28 -> 0.067901542 | O33: =$D57*O$28 -> 0.15770923 | P33: =SUM(E33:O33) -> 3.9860347
B34: Generating Profile with 80% Coincidence Factor | C34: 5 | D34: =HouseholdLoadProfiles!F9 -> 3.6663 | E34: =$D34*E$28 -> 1.83315 | F34: =$D35*F$28 -> 0.549945 | G34: =$D33*G$28 -> 0.549945 | H34: =$D36*H$28 -> 0.2286438 | I34: =$D32*I$28 -> 0.183315 | J34: =$D37*J$28 -> 0.1143219 | K34: =$D31*K$28 -> 0.0916575 | L34: =$D38*L$28 -> 0.27160617 | M34: =$D30*M$28 -> 0.073326 | N34: =$D39*N$28 -> 0.067901542 | O34: =$D58*O$28 -> 0.04082925 | P34: =SUM(E34:O34) -> 4.0046412
B35: Generating Profile with 80% Coincidence Factor | C35: 6 | D35: =HouseholdLoadProfiles!F10 -> 3.6663 | E35: =$D35*E$28 -> 1.83315 | F35: =$D36*F$28 -> 0.6859314 | G35: =$D34*G$28 -> 0.549945 | H35: =$D37*H$28 -> 0.2286438 | I35: =$D33*I$28 -> 0.183315 | J35: =$D38*J$28 -> 0.33950771 | K35: =$D32*K$28 -> 0.0916575 | L35: =$D39*L$28 -> 0.27160617 | M35: =$D31*M$28 -> 0.073326 | N35: =$D40*N$28 -> 0.067901542 | O35: =$D30*O$28 -> 0.0183315 | P35: =SUM(E35:O35) -> 4.3433156
B36: Generating Profile with 80% Coincidence Factor | C36: 7 | D36: =HouseholdLoadProfiles!F11 -> 4.572876 | E36: =$D36*E$28 -> 2.286438 | F36: =$D37*F$28 -> 0.6859314 | G36: =$D35*G$28 -> 0.549945 | H36: =$D38*H$28 -> 0.67901543 | I36: =$D34*I$28 -> 0.183315 | J36: =$D39*J$28 -> 0.33950771 | K36: =$D33*K$28 -> 0.0916575 | L36: =$D40*L$28 -> 0.27160617 | M36: =$D32*M$28 -> 0.073326 | N36: =$D41*N$28 -> 0.074700863 | O36: =$D31*O$28 -> 0.0183315 | P36: =SUM(E36:O36) -> 5.2537746
B37: Generating Profile with 80% Coincidence Factor | C37: 8 | D37: =HouseholdLoadProfiles!F12 -> 4.572876 | E37: =$D37*E$28 -> 2.286438 | F37: =$D38*F$28 -> 2.0370463 | G37: =$D36*G$28 -> 0.6859314 | H37: =$D39*H$28 -> 0.67901543 | I37: =$D35*I$28 -> 0.183315 | J37: =$D40*J$28 -> 0.33950771 | K37: =$D34*K$28 -> 0.0916575 | L37: =$D41*L$28 -> 0.29880345 | M37: =$D33*M$28 -> 0.073326 | N37: =$D42*N$28 -> 0.041412525 | O37: =$D32*O$28 -> 0.0183315 | P37: =SUM(E37:O37) -> 6.7347848
B38: Generating Profile with 80% Coincidence Factor | C38: 9 | D38: =HouseholdLoadProfiles!F13 -> 13.580308 | E38: =$D38*E$28 -> 6.7901542 | F38: =$D39*F$28 -> 2.0370463 | G38: =$D37*G$28 -> 0.6859314 | H38: =$D40*H$28 -> 0.67901543 | I38: =$D36*I$28 -> 0.2286438 | J38: =$D41*J$28 -> 0.37350431 | K38: =$D35*K$28 -> 0.0916575 | L38: =$D42*L$28 -> 0.1656501 | M38: =$D34*M$28 -> 0.073326 | N38: =$D43*N$28 -> 0.041412525 | O38: =$D33*O$28 -> 0.0183315 | P38: =SUM(E38:O38) -> 11.184673
B39: Generating Profile with 80% Coincidence Factor | C39: 10 | D39: =HouseholdLoadProfiles!F14 -> 13.580308 | E39: =$D39*E$28 -> 6.7901542 | F39: =$D40*F$28 -> 2.0370463 | G39: =$D38*G$28 -> 2.0370463 | H39: =$D41*H$28 -> 0.74700863 | I39: =$D37*I$28 -> 0.2286438 | J39: =$D42*J$28 -> 0.20706262 | K39: =$D36*K$28 -> 0.1143219 | L39: =$D43*L$28 -> 0.1656501 | M39: =$D35*M$28 -> 0.073326 | N39: =$D44*N$28 -> 0.041412525 | O39: =$D34*O$28 -> 0.0183315 | P39: =SUM(E39:O39) -> 12.460004
B40: Generating Profile with 80% Coincidence Factor | C40: 11 | D40: =HouseholdLoadProfiles!F15 -> 13.580308 | E40: =$D40*E$28 -> 6.7901542 | F40: =$D41*F$28 -> 2.2410259 | G40: =$D39*G$28 -> 2.0370463 | H40: =$D42*H$28 -> 0.41412525 | I40: =$D38*I$28 -> 0.67901543 | J40: =$D43*J$28 -> 0.20706262 | K40: =$D37*K$28 -> 0.1143219 | L40: =$D44*L$28 -> 0.1656501 | M40: =$D36*M$28 -> 0.09145752 | N40: =$D45*N$28 -> 0.024205912 | O40: =$D35*O$28 -> 0.0183315 | P40: =SUM(E40:O40) -> 12.782397
B41: Generating Profile with 80% Coincidence Factor | C41: 12 | D41: =HouseholdLoadProfiles!F16 -> 14.940173 | E41: =$D41*E$28 -> 7.4700863 | F41: =$D42*F$28 -> 1.2423757 | G41: =$D40*G$28 -> 2.0370463 | H41: =$D43*H$28 -> 0.41412525 | I41: =$D39*I$28 -> 0.67901543 | J41: =$D44*J$28 -> 0.20706262 | K41: =$D38*K$28 -> 0.33950771 | L41: =$D45*L$28 -> 0.09682365 | M41: =$D37*M$28 -> 0.09145752 | N41: =$D46*N$28 -> 0.024205912 | O41: =$D36*O$28 -> 0.02286438 | P41: =SUM(E41:O41) -> 12.624571
B42: Generating Profile with 80% Coincidence Factor | C42: 13 | D42: =HouseholdLoadProfiles!F17 -> 8.282505 | E42: =$D42*E$28 -> 4.1412525 | F42: =$D43*F$28 -> 1.2423757 | G42: =$D41*G$28 -> 2.2410259 | H42: =$D44*H$28 -> 0.41412525 | I42: =$D40*I$28 -> 0.67901543 | J42: =$D45*J$28 -> 0.12102956 | K42: =$D39*K$28 -> 0.33950771 | L42: =$D46*L$28 -> 0.09682365 | M42: =$D38*M$28 -> 0.27160617 | N42: =$D47*N$28 -> 0.076742325 | O42: =$D37*O$28 -> 0.02286438 | P42: =SUM(E42:O42) -> 9.6463686
B43: Generating Profile with 80% Coincidence Factor | C43: 14 | D43: =HouseholdLoadProfiles!F18 -> 8.282505 | E43: =$D43*E$28 -> 4.1412525 | F43: =$D44*F$28 -> 1.2423757 | G43: =$D42*G$28 -> 1.2423757 | H43: =$D45*H$28 -> 0.24205912 | I43: =$D41*I$28 -> 0.74700863 | J43: =$D46*J$28 -> 0.12102956 | K43: =$D40*K$28 -> 0.33950771 | L43: =$D47*L$28 -> 0.3069693 | M43: =$D39*M$28 -> 0.27160617 | N43: =$D48*N$28 -> 0.11962137 | O43: =$D38*O$28 -> 0.067901542 | P43: =SUM(E43:O43) -> 8.8417074
B44: Generating Profile with 80% Coincidence Factor | C44: 15 | D44: =HouseholdLoadProfiles!F19 -> 8.282505 | E44: =$D44*E$28 -> 4.1412525 | F44: =$D45*F$28 -> 0.72617737 | G44: =$D43*G$28 -> 1.2423757 | H44: =$D46*H$28 -> 0.24205912 | I44: =$D42*I$28 -> 0.41412525 | J44: =$D47*J$28 -> 0.38371163 | K44: =$D41*K$28 -> 0.37350431 | L44: =$D48*L$28 -> 0.47848548 | M44: =$D40*M$28 -> 0.27160617 | N44: =$D49*N$28 -> 0.22074459 | O44: =$D39*O$28 -> 0.067901542 | P44: =SUM(E44:O44) -> 8.5619437
B45: Generating Profile with 80% Coincidence Factor | C45: 16 | D45: =HouseholdLoadProfiles!F20 -> 4.8411825 | E45: =$D45*E$28 -> 2.4205912 | F45: =$D46*F$28 -> 0.72617737 | G45: =$D44*G$28 -> 1.2423757 | H45: =$D47*H$28 -> 0.76742325 | I45: =$D43*I$28 -> 0.41412525 | J45: =$D48*J$28 -> 0.59810685 | K45: =$D42*K$28 -> 0.20706262 | L45: =$D49*L$28 -> 0.88297836 | M45: =$D41*M$28 -> 0.29880345 | N45: =$D50*N$28 -> 0.32798386 | O45: =$D40*O$28 -> 0.067901542 | P45: =SUM(E45:O45) -> 7.9535296
B46: Generating Profile with 80% Coincidence Factor | C46: 17 | D46: =HouseholdLoadProfiles!F21 -> 4.8411825 | E46: =$D46*E$28 -> 2.4205912 | F46: =$D47*F$28 -> 2.3022698 | G46: =$D45*G$28 -> 0.72617737 | H46: =$D48*H$28 -> 1.1962137 | I46: =$D44*I$28 -> 0.41412525 | J46: =$D49*J$28 -> 1.1037229 | K46: =$D43*K$28 -> 0.20706262 | L46: =$D50*L$28 -> 1.3119355 | M46: =$D42*M$28 -> 0.1656501 | N46: =$D51*N$28 -> 0.3079942 | O46: =$D41*O$28 -> 0.074700863 | P46: =SUM(E46:O46) -> 10.230444
... B48: Generating Profile with 80% Coincidence Factor | C48: 19 | D48: =HouseholdLoadProfiles!F23 -> 23.924274 | E48: =$D48*E$28 -> 11.962137 | F48: =$D49*F$28 -> 6.6223377 | G48: =$D47*G$28 -> 2.3022698 | H48: =$D50*H$28 -> 3.2798387 | I48: =$D46*I$28 -> 0.24205912 | J48: =$D51*J$28 -> 1.539971 | K48: =$D45*K$28 -> 0.12102956 | L48: =$D52*L$28 -> 0.63083691 | M48: =$D44*M$28 -> 0.1656501 | N48: =$D53*N$28 -> 0.04082925 | O48: =$D43*O$28 -> 0.041412525 | P48: =SUM(E48:O48) -> 26.948372
B49: Generating Profile with 80% Coincidence Factor | C49: 20 | D49: =HouseholdLoadProfiles!F24 -> 44.148918 | E49: =$D49*E$28 -> 22.074459 | F49: =$D50*F$28 -> 9.8395159 | G49: =$D48*G$28 -> 3.5886411 | H49: =$D51*H$28 -> 3.079942 | I49: =$D47*I$28 -> 0.76742325 | J49: =$D52*J$28 -> 0.78854614 | K49: =$D46*K$28 -> 0.12102956 | L49: =$D53*L$28 -> 0.163317 | M49: =$D45*M$28 -> 0.09682365 | N49: =$D59*N$28 -> 0.0183315 | O49: =$D44*O$28 -> 0.041412525 | P49: =SUM(E49:O49) -> 40.579442
B50: Generating Profile with 80% Coincidence Factor | C50: 21 | D50: =HouseholdLoadProfiles!F25 -> 65.596773 | E50: =$D50*E$28 -> 32.798386 | F50: =$D51*F$28 -> 9.2398259 | G50: =$D49*G$28 -> 6.6223377 | H50: =$D52*H$28 -> 1.5770923 | I50: =$D48*I$28 -> 1.1962137 | J50: =$D53*J$28 -> 0.20414625 | K50: =$D47*K$28 -> 0.38371163 | L50: =$D59*L$28 -> 0.073326 | M50: =$D46*M$28 -> 0.09682365 | N50: =$D60*N$28 -> 0.0183315 | O50: =$D45*O$28 -> 0.024205912 | P50: =SUM(E50:O50) -> 52.234401
B51: Generating Profile with 80% Coincidence Factor | C51: 22 | D51: =HouseholdLoadProfiles!F26 -> 61.598839 | E51: =$D51*E$28 -> 30.79942 | F51: =$D52*F$28 -> 4.7312768 | G51: =$D50*G$28 -> 9.8395159 | H51: =$D53*H$28 -> 0.4082925 | I51: =$D49*I$28 -> 2.2074459 | J51: =$D59*J$28 -> 0.0916575 | K51: =$D48*K$28 -> 0.59810685 | L51: =$D60*L$28 -> 0.073326 | M51: =$D47*M$28 -> 0.3069693 | N51: =$D61*N$28 -> 0.0183315 | O51: =$D46*O$28 -> 0.024205912 | P51: =SUM(E51:O51) -> 49.098548
B52: Generating Profile with 80% Coincidence Factor | C52: 23 | D52: =HouseholdLoadProfiles!F27 -> 31.541846 | E52: =$D52*E$28 -> 15.770923 | F52: =$D53*F$28 -> 1.2248775 | G52: =$D51*G$28 -> 9.2398259 | H52: =$D59*H$28 -> 0.183315 | I52: =$D50*I$28 -> 3.2798387 | J52: =$D60*J$28 -> 0.0916575 | K52: =$D49*K$28 -> 1.1037229 | L52: =$D61*L$28 -> 0.073326 | M52: =$D48*M$28 -> 0.47848548 | N52: =$D62*N$28 -> 0.0183315 | O52: =$D47*O$28 -> 0.076742325 | P52: =SUM(E52:O52) -> 31.541046
B53: Generating Profile with 80% Coincidence Factor | C53: 24 | D53: =HouseholdLoadProfiles!F28 -> 8.16585 | E53: =$D53*E$28 -> 4.082925 | F53: =$D59*F$28 -> 0.549945 | G53: =$D52*G$28 -> 4.7312768 | H53: =$D60*H$28 -> 0.183315 | I53: =$D51*I$28 -> 3.079942 | J53: =$D61*J$28 -> 0.0916575 | K53: =$D50*K$28 -> 1.6399193 | L53: =$D62*L$28 -> 0.073326 | M53: =$D49*M$28 -> 0.88297836 | N53: =$D63*N$28 -> 0.0183315 | O53: =$D48*O$28 -> 0.11962137 | P53: =SUM(E53:O53) -> 15.453238
B54: Load for "-5 hour" Shift | C54: 20 | D54: =D49 -> 44.148918
B55: Load for "-4 hour" Shift | C55: 21 | D55: =D50 -> 65.596773
B56: Load for "-3 hour" Shift | C56: 22 | D56: =D51 -> 61.598839
B57: Load for "-2 hour" Shift | C57: 23 | D57: =D52 -> 31.541846
B58: Load for "-1 hour" Shift | C58: 24 | D58: =D53 -> 8.16585
B59: Load for "+1 hour" Shift | C59: 1 | D59: =D30 -> 3.6663
B60: Load for "+2 hour" Shift | C60: 2 | D60: =D31 -> 3.6663
B61: Load for "+3 hour" Shift | C61: 3 | D61: =D32 -> 3.6663
B62: Load for "+4 hour" Shift | C62: 4 | D62: =D33 -> 3.6663
B63: Load for "+5 hour" Shift | C63: 5 | D63: =D34 -> 3.6663
